Workbook

Sheet BDAYS
B2: Player | C2: Position | D2: Team | E2: Birthday | F2: Calc | G2: Days +/-
B3: Tyler Higbee | C3: TE | D3: LAR | E3: 33970 | F3: 45658 | G3: =TODAY()-F3 -> 558
B4: Colby Parkinson | C4: TE | D4: LAR | E4: 36168 | F4: 45665 | G4: =TODAY()-F4 -> 551
B5: Dillon Gabriel | C5: QB | D5: CLE | E5: 36888 | F5: 46019 | G5: =TODAY()-F5 -> 197
B6: Brenton Strange | C6: TE | D6: JAX | E6: 36887 | F6: 46018 | G6: =TODAY()-F6 -> 198
B7: Greg Zuerlein | C7: K | D7: FA | E7: 32138 | F7: 46018 | G7: =TODAY()-F7 -> 198
B8: Zach Charbonnet | C8: RB | D8: SEA | E8: 36899 | F8: 45665 | G8: =TODAY()-F8 -> 551
B9: D'Andre Swift | C9: RB | D9: CHI | E9: 36174 | F9: 45671 | G9: =TODAY()-F9 -> 545
B10: Jeremy McNichols | C10: RB | D10: WAS | E10: 35059 | F10: 46017 | G10: =TODAY()-F10 -> 199
B11: Joshua Dobbs | C11: QB | D11: NE | E11: 34725 | F11: 45683 | G11: =TODAY()-F11 -> 533
B12: Ka'imi Fairbairn | C12: K | D12: HOU | E12: 34363 | F12: 45686 | G12: =TODAY()-F12 -> 530
B13: Hunter Renfrow | C13: WR | D13: CAR | E13: 35054 | F13: 46012 | G13: =TODAY()-F13 -> 204
B14: Calvin Ridley | C14: WR | D14: TEN | E14: 34688 | F14: 46011 | G14: =TODAY()-F14 -> 205
... B448: Jarquez Hunter | C448: RB | D448: LAR | E448: 37619 | F448: 46020 | G448: =TODAY()-F448 -> 196

Sheet SB
B2: Super Bowl Championships
B3: # | C3: Game | D3: Date | E3: Season | F3: Winning team | G3: W | H3: PtsW | I3: PtsL | J3: L | K3: Losing team | L3: OT | M3: Venue | N3: City | O3: Attendance | P3: MVP | Q3: Position | R3: Referee | T3: Franchise | U3: SB Wins | W3: Franchise | X3: SB Losses
B4: 62 | C4: LXII | D4: 46796 | E4: 2027 | M4: Mercedes-Benz Stadium | N4: Atlanta, GA | T4: PIT | U4: 6 | W4: NE | X4: 6
B5: 61 | C5: LXI | D5: 46432 | E5: 2026 | M5: SoFi Stadium | N5: Inglewood, CA | T5: NE | U5: 6 | W5: DEN | X5: 5
B6: 60 | C6: LX | D6: 46061 | E6: 2025 | F6: Seattle Seahawks | G6: SEA | H6: 29 | I6: 13 | J6: NE | K6: New England Patriots | L6: No | M6: Levi's Stadium | N6: Santa Clara, CA | P6: Kenneth Walker III | Q6: RB | T6: DAL | U6: 5 | W6: MIN | X6: 4
B7: 59 | C7: LIX | D7: 45697 | E7: 2024 | F7: Philadelphia Eagles | G7: PHI | H7: 40 | I7: 22 | J7: KC | K7: Kansas City Chiefs | L7: No | M7: Caesars Superdome | N7: New Orleans, LA | O7: 65719 | P7: Jalen Hurts | Q7: QB | R7: Ron Torbert | T7: SF | U7: 5 | W7: BUF | X7: 4
B8: 58 | C8: LVIII | D8: 45333 | E8: 2023 | F8: Kansas City Chiefs | G8: KC | H8: 25 | I8: 22 | J8: SF | K8: San Francisco 49ers | L8: Yes | M8: Allegiant Stadium | N8: Paradise, NV | O8: 61629 | P8: Patrick Mahomes | Q8: QB | R8: Bill Vinovich | T8: NYG | U8: 4 | W8: DAL | X8: 3
B9: 57 | C9: LVII | D9: 44969 | E9: 2022 | F9: Kansas City Chiefs | G9: KC | H9: 38 | I9: 35 | J9: PHI | K9: Philadelphia Eagles | L9: No | M9: State Farm Stadium | N9: Glendale, AZ | O9: 67827 | P9: Patrick Mahomes | Q9: QB | R9: Carl Cheffers | T9: GB | U9: 4 | W9: MIA | X9: 3
B10: 56 | C10: LVI | D10: 44605 | E10: 2021 | F10: Los Angeles Rams | G10: LAR | H10: 23 | I10: 20 | J10: CIN | K10: Cincinnati Bengals | L10: No | M10: SoFi Stadium | N10: Inglewood, CA | O10: 70048 | P10: Cooper Kupp | Q10: WR | R10: Ron Torbert | T10: KC | U10: 4 | W10: PHI | X10: 3
B11: 55 | C11: LV | D11: 44234 | E11: 2020 | F11: Tampa Bay Buccaneers | G11: TB | H11: 31 | I11: 9 | J11: KC | K11: Kansas City Chiefs | L11: No | M11: Raymond James Stadium | N11: Tampa, FL | O11: 24835 | P11: Tom Brady | Q11: QB | R11: Carl Cheffers | T11: WAS | U11: 3 | W11: SF | X11: 3
B12: 54 | C12: LIV | D12: 43863 | E12: 2019 | F12: Kansas City Chiefs | G12: KC | H12: 31 | I12: 20 | J12: SF | K12: San Francisco 49ers | L12: No | M12: Hard Rock Stadium | N12: Miami Gardens, FL | O12: 62417 | P12: Patrick Mahomes | Q12: QB | R12: Bill Vinovich | T12: DEN | U12: 3 | W12: CIN | X12: 3
B13: 53 | C13: LIII | D13: 43499 | E13: 2018 | F13: New England Patriots | G13: NE | H13: 13 | I13: 3 | J13: LAR | K13: Los Angeles Rams | L13: No | M13: Mercedes-Benz Stadium | N13: Atlanta, GA | O13: 70081 | P13: Julian Edelman | Q13: WR | R13: John Parry | T13: LV | U13: 3 | W13: KC | X13: 3
B14: 52 | C14: LII | D14: 43135 | E14: 2017 | F14: Philadelphia Eagles | G14: PHI | H14: 41 | I14: 33 | J14: NE | K14: New England Patriots | L14: No | M14: U.S. Bank Stadium | N14: Minneapolis, MN | O14: 67612 | P14: Nick Foles | Q14: QB | R14: Gene Steratore | T14: PHI | U14: 2 | W14: LAR | X14: 3
B15: 51 | C15: LI | D15: 42771 | E15: 2016 | F15: New England Patriots | G15: NE | H15: 34 | I15: 28 | J15: ATL | K15: Atlanta Falcons | L15: Yes | M15: NRG Stadium | N15: Houston, TX | O15: 70807 | P15: Tom Brady | Q15: QB | R15: Carl Cheffers | T15: MIA | U15: 2 | W15: IND | X15: 2
B16: 50 | C16: L | D16: 42407 | E16: 2015 | F16: Denver Broncos | G16: DEN | H16: 24 | I16: 10 | J16: CAR | K16: Carolina Panthers | L16: No | M16: Levi's Stadium | N16: Santa Clara, CA | O16: 71088 | P16: Von Miller | Q16: LB | R16: Clete Blakeman | T16: SEA | U16: 2 | W16: SEA | X16: 2
B17: 49 | C17: XLIX | D17: 42036 | E17: 2014 | F17: New England Patriots | G17: NE | H17: 28 | I17: 24 | J17: SEA | K17: Seattle Seahawks | L17: No | M17: University of Phoenix Stadium | N17: Glendale, AZ | O17: 70288 | P17: Tom Brady | Q17: QB | R17: Bill Vinovich | T17: LAR | U17: 2 | W17: PIT | X17: 2
B18: 48 | C18: XLVIII | D18: 41672 | E18: 2013 | F18: Seattle Seahawks | G18: SEA | H18: 43 | I18: 8 | J18: DEN | K18: Denver Broncos | L18: No | M18: MetLife Stadium | N18: East Rutherford, NJ | O18: 82529 | P18: Malcolm Smith | Q18: LB | R18: Terry McAulay | T18: IND | U18: 2 | W18: LV | X18: 2
... B23: 43 | C23: XLIII | D23: 39845 | E23: 2008 | F23: Pittsburgh Steelers | G23: PIT | H23: 27 | I23: 23 | J23: ARI | K23: Arizona Cardinals | L23: No | M23: Raymond James Stadium | N23: Tampa, FL | O23: 70774 | P23: Santonio Holmes | Q23: WR | R23: Terry McAulay | T23: NO | U23: 1 | W23: TEN | X23: 1
B24: 42 | C24: XLII | D24: 39481 | E24: 2007 | F24: New York Giants | G24: NYG | H24: 17 | I24: 14 | J24: NE | K24: New England Patriots | L24: No | M24: University of Phoenix Stadium | N24: Glendale, AZ | O24: 71101 | P24: Eli Manning | Q24: QB | R24: Mike Carey | T24: (blank) | W24: ARI | X24: 1
B25: 41 | C25: XLI | D25: 39117 | E25: 2006 | F25: Indianapolis Colts | G25: IND | H25: 29 | I25: 17 | J25: CHI | K25: Chicago Bears | L25: No | M25: Dolphin Stadium | N25: Miami Gardens, FL | O25: 74512 | P25: Peyton Manning | Q25: QB | R25: Tony Corrente | T25: Grand Total | U25: 60 | W25: CHI | X25: 1
B26: 40 | C26: XL | D26: 38753 | E26: 2005 | F26: Pittsburgh Steelers | G26: PIT | H26: 21 | I26: 10 | J26: SEA | K26: Seattle Seahawks | L26: No | M26: Ford Field | N26: Detroit, MI | O26: 68206 | P26: Hines Ward | Q26: WR | R26: Bill Leavy | W26: GB | X26: 1
B27: 39 | C27: XXXIX | D27: 38389 | E27: 2004 | F27: New England Patriots | G27: NE | H27: 24 | I27: 21 | J27: PHI | K27: Philadelphia Eagles | L27: No | M27: Alltel Stadium | N27: Jacksonville, FL | O27: 78125 | P27: Deion Branch | Q27: WR | R27: Terry McAulay | W27: NYG | X27: 1
B28: 38 | C28: XXXVIII | D28: 38018 | E28: 2003 | F28: New England Patriots | G28: NE | H28: 32 | I28: 29 | J28: CAR | K28: Carolina Panthers | L28: No | M28: Reliant Stadium | N28: Houston, TX | O28: 71525 | P28: Tom Brady | Q28: QB | R28: Ed Hochuli | W28: (blank)
B29: 37 | C29: XXXVII | D29: 37647 | E29: 2002 | F29: Tampa Bay Buccaneers | G29: TB | H29: 48 | I29: 21 | J29: LV | K29: Oakland Raiders | L29: No | M29: Qualcomm Stadium | N29: San Diego, CA | O29: 67603 | P29: Dexter Jackson | Q29: S | R29: Bill Carollo | W29: Grand Total | X29: 60
B30: 36 | C30: XXXVI | D30: 37290 | E30: 2001 | F30: New England Patriots | G30: NE | H30: 20 | I30: 17 | J30: LAR | K30: St. Louis Rams | L30: No | M30: LA Superdome | N30: New Orleans, LA | O30: 72922 | P30: Tom Brady | Q30: QB | R30: Bernie Kukar
B31: 35 | C31: XXXV | D31: 36919 | E31: 2000 | F31: Baltimore Ravens | G31: BAL | H31: 34 | I31: 7 | J31: NYG | K31: New York Giants | L31: No | M31: Raymond James Stadium | N31: Tampa, FL | O31: 71921 | P31: Ray Lewis | Q31: LB | R31: Gerry Austin
B32: 34 | C32: XXXIV | D32: 36555 | E32: 1999 | F32: St. Louis Rams | G32: LAR | H32: 23 | I32: 16 | J32: TEN | K32: Tennessee Titans | L32: No | M32: GA Dome | N32: Atlanta, GA | O32: 72625 | P32: Kurt Warner | Q32: QB | R32: Bob McElwee
B33: 33 | C33: XXXIII | D33: 36191 | E33: 1998 | F33: Denver Broncos | G33: DEN | H33: 34 | I33: 19 | J33: ATL | K33: Atlanta Falcons | L33: No | M33: Pro Player Stadium | N33: Miami, FL | O33: 74803 | P33: John Elway | Q33: QB | R33: Bernie Kukar
B34: 32 | C34: XXXII | D34: 35820 | E34: 1997 | F34: Denver Broncos | G34: DEN | H34: 31 | I34: 24 | J34: GB | K34: Green Bay Packers | L34: No | M34: Qualcomm Stadium | N34: San Diego, CA | O34: 68912 | P34: Terrell Davis | Q34: RB | R34: Ed Hochuli
B35: 31 | C35: XXXI | D35: 35456 | E35: 1996 | F35: Green Bay Packers | G35: GB | H35: 35 | I35: 21 | J35: NE | K35: New England Patriots | L35: No | M35: LA Superdome | N35: New Orleans, LA | O35: 72301 | P35: Desmond Howard | Q35: KR | R35: Gerry Austin
B36: 30 | C36: XXX | D36: 35092 | E36: 1995 | F36: Dallas Cowboys | G36: DAL | H36: 27 | I36: 17 | J36: PIT | K36: Pittsburgh Steelers | L36: No | M36: Sun Devil Stadium | N36: Tempe, AZ | O36: 76347 | P36: Larry Brown | Q36: CB | R36: Red Cashion
B37: 29 | C37: XXIX | D37: 34728 | E37: 1994 | F37: San Francisco 49ers | G37: SF | H37: 49 | I37: 26 | J37: LAC | K37: San Diego Chargers | L37: No | M37: Joe Robbie Stadium | N37: Miami, FL | O37: 74107 | P37: Steve Young | Q37: QB | R37: Jerry Markbreit
B38: 28 | C38: XXVIII | D38: 34364 | E38: 1993 | F38: Dallas Cowboys | G38: DAL | H38: 30 | I38: 13 | J38: BUF | K38: Buffalo Bills | L38: No | M38: GA Dome | N38: Atlanta, GA | O38: 72817 | P38: Emmit Smith | Q38: RB | R38: Bob McElwee
B39: 27 | C39: XXVII | D39: 34000 | E39: 1992 | F39: Dallas Cowboys | G39: DAL | H39: 52 | I39: 17 | J39: BUF | K39: Buffalo Bills | L39: No | M39: Rose Bowl | N39: Pasadena, CA | O39: 98374 | P39: Troy Aikman | Q39: QB | R39: Dick Hantak
B40: 26 | C40: XXVI | D40: 33629 | E40: 1991 | F40: Washington Redskins | G40: WAS | H40: 37 | I40: 24 | J40: BUF | K40: Buffalo Bills | L40: No | M40: Metrodome | N40: Minneapolis, MN | O40: 63130 | P40: Mary Rypien | Q40: QB | R40: Jerry Markbreit
B41: 25 | C41: XXV | D41: 33265 | E41: 1990 | F41: New York Giants | G41: NYG | H41: 20 | I41: 19 | J41: BUF | K41: Buffalo Bills | L41: No | M41: Tampa Stadium | N41: Tampa, FL | O41: 73813 | P41: Ottis Anderson | Q41: RB | R41: Jerry Seeman
... B65: 1 | C65: I | D65: 24487 | E65: 1966 | F65: Green Bay Packers | G65: GB | H65: 35 | I65: 10 | J65: KC | K65: Kansas City Chiefs | L65: No | M65: Los Angeles Memorial Coliseum | N65: Los Angeles, CA | O65: 61946 | P65: Bart Starr | Q65: QB | R65: Norm Schachter

Sheet CHAMPS
B2: Date | C2: Season | D2: MLB | E2: NBA | F2: NHL | G2: NFL | H2: SBl | I2: SBc | J2: NFLl
B3: 2028 | C3: 2027 | G3: Falcons | H3: Mercedes-Benz Stadium | I3: Atlanta, GA
B4: 2027 | C4: 2026 | G4: Rams/Chargers | H4: SoFi Stadium | I4: Inglewood, CA
B5: 2026 | C5: 2025 | G5: Seattle Seahawks | H5: Levi's Stadium | I5: Santa Clara, CA
B6: 2025 | C6: 2024 | D6: Los Angeles Dodgers | E6: Oklahoma City Thunder | F6: Florida Panthers | G6: Philadelphia Eagles | H6: Caesars Superdome | I6: New Orleans, LA | J6: Kansas City Chiefs
B7: 2024 | C7: 2023 | D7: Los Angeles Dodgers | E7: Boston Celtics | F7: Florida Panthers | G7: Kansas City Chiefs | H7: Allegiant Stadium | I7: Paradise, NV | J7: San Francisco 49ers
B8: 2023 | C8: 2022 | D8: Texas Rangers | E8: Denver Nuggets | F8: Vegas Golden Knights | G8: Kansas City Chiefs | H8: State Farm Stadium | I8: Glendale, AZ | J8: Philadelphia Eagles
B9: 2022 | C9: 2021 | D9: Houston Astros | E9: Golden State Warriors | F9: Colorado Avalanche | G9: Los Angeles Rams | H9: SoFi Stadium | I9: Inglewood, CA | J9: Cincinnati Bengals
B10: 2021 | C10: 2020 | D10: Atlanta Braves | E10: Milwaukee Bucks | F10: Tampa Bay Lightning | G10: Tampa Bay Buccaneers | H10: Raymond James Stadium | I10: Tampa, FL | J10: Kansas City Chiefs
B11: 2020 | C11: 2019 | D11: Los Angeles Dodgers | E11: Los Angeles Lakers | F11: Tampa Bay Lightning | G11: Kansas City Chiefs | H11: Hard Rock Stadium | I11: Miami Gardens, FL | J11: San Francisco 49ers
B12: 2019 | C12: 2018 | D12: Washington Nationals | E12: Toronto Raptors | F12: St. Louis Blues | G12: New England Patriots | H12: Mercedes-Benz Stadium | I12: Atlanta, GA | J12: Los Angeles Rams
B13: 2018 | C13: 2017 | D13: Boston Red Sox | E13: Golden State Warriors | F13: Washington Capitals | G13: Philadelphia Eagles | H13: U.S. Bank Stadium | I13: Minneapolis, MN | J13: New England Patriots
B14: 2017 | C14: 2016 | D14: Houston Astros | E14: Golden State Warriors | F14: Pittsburgh Penguins | G14: New England Patriots | H14: NRG Stadium | I14: Houston, TX | J14: Atlanta Falcons
B15: 2016 | C15: 2015 | D15: Chicago Cubs | E15: Cleveland Cavaliers | F15: Pittsburgh Penguins | G15: Denver Broncos | H15: Levi's Stadium | I15: Santa Clara, CA | J15: Carolina Panthers
B16: 2015 | C16: 2014 | D16: Kansas City Royals | E16: Golden State Warriors | F16: Chicago Blackhawks | G16: New England Patriots | H16: University of Phoenix Stadium | I16: Glendale, AZ | J16: Seattle Seahawks
B17: 2014 | C17: 2013 | D17: San Francisco Giants | E17: San Antonio Spurs | F17: Los Angeles Kings | G17: Seattle Seahawks | H17: MetLife Stadium | I17: East Rutherford, NJ | J17: Denver Broncos
... B64: 1967 | C64: 1966 | D64: Baltimore Orioles | E64: Indiana Pacers | F64: Toronto Maple Leafs | G64: Green Bay Packers | H64: Los Angeles Memorial Coliseum | I64: Los Angeles, CA | J64: Kansas City Chiefs
D65: Los Angeles Dodgers | E65: Milwaukee Bucks | F65: Montreal Canadiens
D66: St. Louis Cardinals | E66: Utah Stars | F66: Montreal Canadiens
D67: Los Angeles Dodgers | E67: New York Knicks | F67: Toronto Maple Leafs
D68: New York Yankees | E68: Indiana Pacers | F68: Toronto Maple Leafs
D69: New York Yankees | E69: Boston Celtics | F69: Toronto Maple Leafs
D70: Pittsburgh Pirates | E70: Oakland Oaks | F70: Chicago Black Hawks
D71: Los Angeles Dodgers | E71: Boston Celtics | F71: Montreal Canadiens
D72: New York Yankees | E72: Pittsburgh Pipers | F72: Montreal Canadiens
D73: Milwaukee Braves | E73: Philadelphia 76ers | F73: Montreal Canadiens
D74: New York Yankees | E74: Boston Celtics | F74: Montreal Canadiens
D75: Brooklyn Dodgers | E75: Boston Celtics | F75: Montreal Canadiens
D76: New York Giants | E76: Boston Celtics | F76: Detroit Red Wings
... D93: New York Yankees | E93: Philadelphia Warriors | F93: Chicago Black Hawks
D94: New York Yankees | F94: Detroit Red Wings
D95: Detroit Tigers | F95: Detroit Red Wings
D96: St. Louis Cardinals | F96: Montreal Maroons
D97: New York Giants | F97: Chicago Black Hawks
D98: New York Yankees | F98: New York Rangers
D99: St. Louis Cardinals | F99: Toronto Maple Leafs
D100: Philadelphia Athletics | F100: Montreal Canadiens
D101: Philadelphia Athletics | F101: Montreal Canadiens
D102: New York Yankees | F102: Boston Bruins
D103: New York Yankees | F103: New York Rangers
...

Sheet Weekly Tracker
A1: TDs
C4: Week 16 | H4: Week 17 | M4: Week 18 | R4: Wildcard
B5: 1 | C5: J. Cook | D5: RB1 | E5: BUF | F5: 1 | G5: 1 | H5: Z. Flowers | I5: WR1 | J5: BAL | K5: 1 | L5: 1 | M5: B. Tuten | N5: RB2 | O5: JAX | P5: 1 | Q5: 1 | R5: B. Purdy | S5: QB1 | T5: SF
B6: 2 | C6: B. Robinson | D6: RB1 | E6: ATL | F6: 1 | G6: 2 | H6: T. McLaurin | I6: WR1 | J6: WAS | K6: 1 | L6: 2 | M6: R. Davis | N6: RB1 | O6: BUF | P6: 1 | Q6: 2 | R6: T. Etienne Jr. | S6: RB1 | T6: JAX
B7: 3 | C7: T. Spears | D7: RB2 | E7: TEN | F7: 1 | G7: 3 | H7: T. McBride | I7: TE1 | J7: ARI | K7: 1 | L7: 3 | M7: J. Higgins | N7: WR2 | O7: HOU | P7: 1 | Q7: 3 | R7: C. McCaffrey | S7: RB1 | T7: SF
B8: 4 | C8: C. Sutton | D8: WR1 | E8: DEN | F8: 1 | G8: 4 | H8: R. Stevenson | I8: RB2 | J8: NE | K8: 1 | L8: 4 | M8: T. Bigsby | N8: RB1 | O8: JAX | P8: 1 | Q8: 4 | R8: K. Williams | S8: RB1 | T8: LAR
B9: 5 | C9: L. McConkey | D9: WR1 | E9: LAC | F9: 1 | G9: 5 | H9: O. Gadsden | I9: TE1 | J9: LAC | K9: 1 | L9: 5 | M9: P. Nacua | N9: WR1 | O9: LAR | P9: 1 | Q9: 5 | R9: C. Watson | S9: WR1 | T9: GB
B10: 6 | C10: Z. Flowers | D10: WR1 | E10: BAL | F10: 1 | G10: 6 | H10: J. Jennings | I10: WR1 | J10: SF | K10: 1 | L10: 6 | M10: A. St. Brown | N10: WR1 | O10: DET | P10: 1 | Q10: 6 | R10: T. McMillan | S10: WR1 | T10: CAR
B11: 7 | C11: K. Pitts | D11: TE1 | E11: ATL | F11: 1 | G11: 7 | H11: J. Ferguson | I11: TE1 | J11: DAL | K11: 1 | L11: 7 | M11: J. Coker | N11: WR2 | O11: CAR | P11: 1 | Q11: 7 | R11: D. Smith | S11: WR2 | T11: PHI
B12: 8 | C12: B. Bowers | D12: TE1 | E12: LV | F12: 1 | G12: 8 | H12: J. Dart | I12: QB1 | J12: NYG | K12: 1 | L12: 8 | M12: T. Tremble | N12: TE1 | O12: CAR | P12: 1 | Q12: 8 | R12: Q. Johnston | S12: WR2 | T12: LAC
B13: 9 | C13: D. Goedert | D13: TE1 | E13: PHI | F13: 1 | G13: 9 | H13: J. Chase | I13: WR1 | J13: CIN | K13: 1 | L13: 9 | M13: C. Heyward | N13: TE2 | O13: PIT | P13: 1 | Q13: 9 | R13: C. Austin III | S13: WR2 | T13: PIT
B14: 10 | C14: S. Barkley | D14: RB1 | E14: PHI | F14: 1 | G14: 10 | H14: H. Fannin | I14: TE1 | J14: CLE | K14: 1 | L14: 10 | M14: T. Higgins | N14: WR2 | O14: CIN | P14: 1 | Q14: 10 | R14: D. Schultz | S14: TE1 | T14: HOU
B15: 11 | C15: J. Smith-Njigba | D15: WR1 | E15: SEA | F15: 1 | G15: 11 | H15: D. Goedert | I15: TE1 | J15: PHI | K15: 1 | L15: 11 | M15: Z. Flowers | N15: WR1 | O15: BAL | P15: 1 | Q15: 11
B16: 12 | C16: T. Ferguson | D16: TE1 | E16: LAR | F16: 1 | G16: 12 | H16: C. Olave | I16: WR1 | J16: NO | K16: 1 | L16: 12 | M16: J. Dart | N16: QB1 | O16: NYG | P16: 0 | Q16: 12
B17: 13 | C17: R. Doubs | D17: WR2 | E17: GB | F17: 1 | G17: 13 | H17: C. Godwin | I17: WR2 | J17: TB | K17: 1 | L17: 13 | M17: B. Young | N17: QB1 | O17: CAR | P17: 0 | Q17: 13
B18: 14 | C18: B. Irving | D18: RB1 | E18: TB | F18: 0 | G18: 14 | H18: B. Nix | I18: QB1 | J18: DEN | K18: 1 | L18: 14 | M18: C. Oladokun | N18: QB1 | O18: KC | P18: 0 | Q18: 14
B19: 15 | C19: J. Johnson | D19: TE1 | E19: NO | F19: 0 | G19: 15 | H19: J. Reed | I19: WR3 | J19: GB | K19: 0 | L19: 15 | M19: G. Pickens | N19: WR2 | O19: DAL | P19: 0 | Q19: 15
B20: 16 | C20: J. Ferguson | D20: TE1 | E20: DAL | F20: 0 | G20: 16 | H20: D. Waller | I20: TE1 | J20: MIA | K20: 0 | L20: 16 | M20: B. Whiteheart | N20: TE1 | O20: CLE | P20: 0 | Q20: 16
B21: 17 | C21: B. Nix | D21: QB1 | E21: DEN | F21: 0 | G21: 17 | H21: D. Schultz | I21: TE1 | J21: HOU | K21: 0 | L21: 17 | M21: A. Hooper | N21: TE2 | O21: NE | P21: 0 | Q21: 17
B22: 18 | C22: A. St. Brown | D22: WR1 | E22: DET | F22: 0 | G22: 18 | H22: D. London | I22: WR1 | J22: ATL | K22: 0 | L22: 18 | M22: I. Likely | N22: TE1 | O22: BAL | P22: 0 | Q22: 18
B23: 19 | C23: I. Likely | D23: TE2 | E23: BAL | F23: 0 | G23: 19 | H23: D. Achane | I23: RB1 | J23: MIA | K23: 0 | L23: 19 | M23: D. Henry | N23: RB1 | O23: BAL | P23: 0 | Q23: 19
B24: 20 | C24: J. Goff | D24: QB1 | E24: DET | F24: 0 | G24: 20 | H24: A. Thielen | I24: WR2 | J24: PIT | K24: 0 | L24: 20 | M24: D.J. Moore | N24: WR1 | O24: CHI | P24: 0 | Q24: 20
C25: =SUM(F5:F24)/COUNTA(C5:C24) -> 0.65 | H25: =SUM(K5:K24)/COUNTA(H5:H24) -> 0.7 | M25: =SUM(P5:P24)/COUNTA(M5:M24) -> 0.55 | R25: =SUM(U5:U24)/COUNTA(R5:R24) -> 0

Sheet test
B1: PLAYER INFO | G1: PASS/RUSH RANKS | L1: REC RANKS | N1: TD | O1: PASS/RUSH ALLOWED | T1: REC ALLOWED | V1: TD | W1: *
B2: Player | C2: Team | D2: Pos. | E2: Slate | F2: Opp | G2: *P* | H2: *P+R* | I2: *P TD* | J2: *R* | K2: *R+R* | L2: *C* | M2: *Y* | N2: *TD* | O2: P | P2: P+R | Q2: P TD | R2: R | S2: R+R | T2: C | U2: Y | V2: TD | W2: * | X2: Column1
B3: B. Irving | C3: TB | D3: RB1 | E3: {=_xlfn.XLOOKUP(Table117821341[[#This Row],[Team]],Table4334[Team],'2425'!$C$3:$C$34)} -> n/a | F3: =_xlfn.XLOOKUP(Table117821341[[#This Row],[Team]],Table4334[Team],Table4334[OPP]) -> n/a | G3: {=IF(Table117821341[[#This Row],[Pos.]]="QB1",_xlfn.XLOOKUP(Table117821341[[#This Row],[Opp]],Table123[DEF],'2425'!$G$3:$G$34),"#N/A")} -> #N/A | H3: {=IF(Table117821341[[#This Row],[Pos.]]="QB1",_xlfn.XLOOKUP(Table117821341[[#This Row],[Opp]],Table123[DEF],'2425'!$J$3:$J$34),"#N/A")} -> #N/A | I3: {=IF(Table117821341[[#This Row],[Pos.]]="QB1",_xlfn.XLOOKUP(Table117821341[[#This Row],[Opp]],Table123[DEF],'2425'!$K$3:$K$34),"#N/A")} -> #N/A | J3: {=_xlfn.IFS(Table117821341[[#This Row],[Pos.]]="QB1",_xlfn.XLOOKUP(Table117821341[[#This Row],[Opp]],Table123[DEF],'2425'!$I$3:$I$34),Table117821341[[#This Row],[Pos.]]="RB1",_xlfn.XLOOKUP(Table117821341[[#This Row],[Opp]],Table2040[DEF],'2425'!$H$38:$H$69),Table117821341[[#This Row],[Pos.]]="RB2",_xlfn.XLOOKUP(Table117821341[[#This Row],[Opp]],Table2040[DEF],'2425'!$H$38:$H$69))} -> #N/A | K3: {=_xlfn.IFS(Table117821341[[#This Row],[Pos.]]="RB1",_xlfn.XLOOKUP(Table117821341[[#This Row],[Opp]],Table2040[DEF],'2425'!$K$38:$K$69),Table117821341[[#This Row],[Pos.]]="RB2",_xlfn.XLOOKUP(Table117821341[[#This Row],[Opp]],Table2040[DEF],'2425'!$K$38:$K$69))} -> #N/A | L3: {=_xlfn.IFS(Table117821341[[#This Row],[Pos.]]="WR1",_xlfn.XLOOKUP(Table117821341[[#This Row],[Opp]],Table731[DEF],'2425'!$U$3:$U$34),Table117821341[[#This Row],[Pos.]]="WR2",_xlfn.XLOOKUP(Table117821341[[#This Row],[Opp]],Table71236[DEF],'2425'!$AD$3:$AD$34),Table117821341[[#This Row],[Pos.]]="WR3",_xlfn.XLOOKUP(Table117821341[[#This Row],[Opp]],Table7121437[DEF],'2425'!$U$38:$U$69),Table117821341[[#This Row],[Pos.]]="WR4",_xlfn.XLOOKUP(Table117821341[[#This Row],[Opp]],Table712141538[DEF],'2425'!$AD$38:$AD$69),Table117821341[[#This Row],[Pos.]]="TE1",_xlfn.XLOOKUP(Table117821341[[#This Row],[Opp]],Table832[DEF],'2425'!$AM$3:$AM$34),Table117821341[[#This Row],[Pos.]]="TE2",_xlfn.XLOOKUP(Table117821341[[#This Row],[Opp]],Table832[DEF],'2425'!$AM$3:$AM$34),Table117821341[[#This Row],[Pos.]]="RB1",_xlfn.XLOOKUP(Table117821341[[#This Row],[Opp]],Table2040[DEF],'2425'!$I$38:$I$69),Table117821341[[#This Row],[Pos.]]="RB2",_xlfn.XLOOKUP(Table117821341[[#This Row],[Opp]],Table2040[DEF],'2425'!$I$38:$I$69))} -> #N/A | M3: {=_xlfn.IFS(Table117821341[[#This Row],[Pos.]]="WR1",_xlfn.XLOOKUP(Table117821341[[#This Row],[Opp]],Table731[DEF],'2425'!$V$3:$V$34),Table117821341[[#This Row],[Pos.]]="WR2",_xlfn.XLOOKUP(Table117821341[[#This Row],[Opp]],Table71236[DEF],'2425'!$AE$3:$AE$34),Table117821341[[#This Row],[Pos.]]="WR3",_xlfn.XLOOKUP(Table117821341[[#This Row],[Opp]],Table7121437[DEF],'2425'!$V$38:$V$69),Table117821341[[#This Row],[Pos.]]="WR4",_xlfn.XLOOKUP(Table117821341[[#This Row],[Opp]],Table712141538[DEF],'2425'!$AE$38:$AE$69),Table117821341[[#This Row],[Pos.]]="TE1",_xlfn.XLOOKUP(Table117821341[[#This Row],[Opp]],Table832[DEF],'2425'!$AN$3:$AN$34),Table117821341[[#This Row],[Pos.]]="TE2",_xlfn.XLOOKUP(Table117821341[[#This Row],[Opp]],Table832[DEF],'2425'!$AN$3:$AN$34),Table117821341[[#This Row],[Pos.]]="RB1",_xlfn.XLOOKUP(Table117821341[[#This Row],[Opp]],Table2040[DEF],'2425'!$J$38:$J$69),Table117821341[[#This Row],[Pos.]]="RB2",_xlfn.XLOOKUP(Table117821341[[#This Row],[Opp]],Table2040[DEF],'2425'!$J$38:$J$69))} -> #N/A | N3: {=_xlfn.IFS(Table117821341[[#This Row],[Pos.]]="WR1",_xlfn.XLOOKUP(Table117821341[[#This Row],[Opp]],Table731[DEF],'2425'!$W$3:$W$34),Table117821341[[#This Row],[Pos.]]="WR2",_xlfn.XLOOKUP(Table117821341[[#This Row],[Opp]],Table71236[DEF],'2425'!$AF$3:$AF$34),Table117821341[[#This Row],[Pos.]]="WR3",_xlfn.XLOOKUP(Table117821341[[#This Row],[Opp]],Table7121437[DEF],'2425'!$W$38:$W$69),Table117821341[[#This Row],[Pos.]]="WR4",_xlfn.XLOOKUP(Table117821341[[#This Row],[Opp]],Table712141538[DEF],'2425'!$AF$38:$AF$69),Table117821341[[#This Row],[Pos.]]="QB1",_xlfn.XLOOKUP(Table117821341[[#This Row],[Opp]],Table123[DEF],'2425'!$L$3:$L$34),Table117821341[[#This Row],[Pos.]]="RB1",_xlfn.XLOOKUP(Table117821341[[#This Row],[Opp]],Table2040[DEF],'2425'!$L$38:$L$69),Table117821341[[#This Row],[Pos.]]="RB2",_xlfn.XLOOKUP(Table117821341[[#This Row],[Opp]],Table2040[DEF],'2425'!$L$38:$L$69),Table117821341[[#This Row],[Pos.]]="TE1",_xlfn.XLOOKUP(Table117821341[[#This Row],[Opp]],Table832[DEF],'2425'!$AO$3:$AO$34),Table117821341[[#This Row],[Pos.]]="TE2",_xlfn.XLOOKUP(Table117821341[[#This Row],[Opp]],Table832[DEF],'2425'!$AO$3:$AO$34),Table117821341[[#This Row],[Pos.]]="D/ST",_xlfn.XLOOKUP(Table117821341[[#This Row],[Opp]],Table1033[DEF],'2425'!$C$38:$C$69))} -> #N/A | O3: =IF(Table117821341[[#This Row],[Pos.]]="QB1",_xlfn.XLOOKUP(Table117821341[[#This Row],[Opp]],Table123[DEF],Table123[P]),"#N/A") -> #N/A | P3: =IF(Table117821341[[#This Row],[Pos.]]="QB1",_xlfn.XLOOKUP(Table117821341[[#This Row],[Opp]],Table123[DEF],Table123[P+R]),"#N/A") -> #N/A | Q3: =IF(Table117821341[[#This Row],[Pos.]]="QB1",_xlfn.XLOOKUP(Table117821341[[#This Row],[Opp]],Table123[DEF],Table123[P TD]),"#N/A") -> #N/A | R3: {=_xlfn.IFS(Table117821341[[#This Row],[Pos.]]="QB1",_xlfn.XLOOKUP(Table117821341[[#This Row],[Opp]],Table123[DEF],Table123[R]),Table117821341[[#This Row],[Pos.]]="RB1",_xlfn.XLOOKUP(Table117821341[[#This Row],[Opp]],Table2040[DEF],Table2040[R]),Table117821341[[#This Row],[Pos.]]="RB2",_xlfn.XLOOKUP(Table117821341[[#This Row],[Opp]],Table2040[DEF],Table2040[R]))} -> #N/A | S3: {=_xlfn.IFS(Table117821341[[#This Row],[Pos.]]="RB1",_xlfn.XLOOKUP(Table117821341[[#This Row],[Opp]],Table2040[DEF],Table2040[R+R]),Table117821341[[#This Row],[Pos.]]="RB2",_xlfn.XLOOKUP(Table117821341[[#This Row],[Opp]],Table2040[DEF],Table2040[R+R]))} -> #N/A | T3: {=_xlfn.IFS(Table117821341[[#This Row],[Pos.]]="RB1",_xlfn.XLOOKUP(Table117821341[[#This Row],[Opp]],Table2040[DEF],Table2040[REC]),Table117821341[[#This Row],[Pos.]]="RB2",_xlfn.XLOOKUP(Table117821341[[#This Row],[Opp]],Table2040[DEF],Table2040[REC]),Table117821341[[#This Row],[Pos.]]="WR1",_xlfn.XLOOKUP(Table117821341[[#This Row],[Opp]],Table731[DEF],Table731[REC]),Table117821341[[#This Row],[Pos.]]="WR2",_xlfn.XLOOKUP(Table117821341[[#This Row],[Opp]],Table71236[DEF],Table71236[REC]),Table117821341[[#This Row],[Pos.]]="WR3",_xlfn.XLOOKUP(Table117821341[[#This Row],[Opp]],Table7121437[DEF],Table7121437[REC]),Table117821341[[#This Row],[Pos.]]="WR4",_xlfn.XLOOKUP(Table117821341[[#This Row],[Opp]],Table712141538[DEF],Table712141538[REC]),Table117821341[[#This Row],[Pos.]]="TE1",_xlfn.XLOOKUP(Table117821341[[#This Row],[Opp]],Table832[DEF],Table832[REC]),Table117821341[[#This Row],[Pos.]]="TE2",_xlfn.XLOOKUP(Table117821341[[#This Row],[Opp]],Table832[DEF],Table832[REC]))} -> #N/A | U3: {=_xlfn.IFS(Table117821341[[#This Row],[Pos.]]="RB1",_xlfn.XLOOKUP(Table117821341[[#This Row],[Opp]],Table2040[DEF],Table2040[Y]),Table117821341[[#This Row],[Pos.]]="RB2",_xlfn.XLOOKUP(Table117821341[[#This Row],[Opp]],Table2040[DEF],Table2040[Y]),Table117821341[[#This Row],[Pos.]]="WR1",_xlfn.XLOOKUP(Table117821341[[#This Row],[Opp]],Table731[DEF],Table731[Y]),Table117821341[[#This Row],[Pos.]]="WR2",_xlfn.XLOOKUP(Table117821341[[#This Row],[Opp]],Table71236[DEF],Table71236[Y]),Table117821341[[#This Row],[Pos.]]="WR3",_xlfn.XLOOKUP(Table117821341[[#This Row],[Opp]],Table7121437[DEF],Table7121437[Y]),Table117821341[[#This Row],[Pos.]]="WR4",_xlfn.XLOOKUP(Table117821341[[#This Row],[Opp]],Table712141538[DEF],Table712141538[Y]),Table117821341[[#This Row],[Pos.]]="TE1",_xlfn.XLOOKUP(Table117821341[[#This Row],[Opp]],Table832[DEF],Table832[Y]),Table117821341[[#This Row],[Pos.]]="TE2",_xlfn.XLOOKUP(Table117821341[[#This Row],[Opp]],Table832[DEF],Table832[Y]))} -> #N/A | V3: {=_xlfn.IFS(Table117821341[[#This Row],[Pos.]]="QB1",_xlfn.XLOOKUP(Table117821341[[#This Row],[Opp]],Table123[DEF],Table123[TD]),Table117821341[[#This Row],[Pos.]]="RB1",_xlfn.XLOOKUP(Table117821341[[#This Row],[Opp]],Table2040[DEF],Table2040[TD]),Table117821341[[#This Row],[Pos.]]="RB2",_xlfn.XLOOKUP(Table117821341[[#This Row],[Opp]],Table2040[DEF],Table2040[TD]),Table117821341[[#This Row],[Pos.]]="WR1",_xlfn.XLOOKUP(Table117821341[[#This Row],[Opp]],Table731[DEF],Table731[TD]),Table117821341[[#This Row],[Pos.]]="WR2",_xlfn.XLOOKUP(Table117821341[[#This Row],[Opp]],Table71236[DEF],Table71236[TD]),Table117821341[[#This Row],[Pos.]]="WR3",_xlfn.XLOOKUP(Table117821341[[#This Row],[Opp]],Table7121437[DEF],Table7121437[TD]),Table117821341[[#This Row],[Pos.]]="WR4",_xlfn.XLOOKUP(Table117821341[[#This Row],[Opp]],Table712141538[DEF],Table712141538[TD]),Table117821341[[#This Row],[Pos.]]="TE1",_xlfn.XLOOKUP(Table117821341[[#This Row],[Opp]],Table832[DEF],Table832[TD]),Table117821341[[#This Row],[Pos.]]="TE2",_xlfn.XLOOKUP(Table117821341[[#This Row],[Opp]],Table832[DEF],Table832[TD]),Table117821341[[#This Row],[Pos.]]="D/ST",_xlfn.XLOOKUP(Table117821341[[#This Row],[Opp]],Table1033[DEF],Table1033[TD]))} -> #N/A | W3: {=_xlfn.IFS(Table117821341[[#This Row],[Pos.]]="QB1",AVERAGE(G3,H3,I3,J3,N3),Table117821341[[#This Row],[Pos.]]="RB1",AVERAGE(J3,K3,N3),Table117821341[[#This Row],[Pos.]]="RB2",AVERAGE(J3,K3,N3),Table117821341[[#This Row],[Pos.]]="WR1",AVERAGE(L3,M3,N3),Table117821341[[#This Row],[Pos.]]="WR2",AVERAGE(L3,M3,N3),Table117821341[[#This Row],[Pos.]]="WR3",AVERAGE(L3,M3,N3),Table117821341[[#This Row],[Pos.]]="WR4",AVERAGE(L3,M3,N3),Table117821341[[#This Row],[Pos.]]="TE1",AVERAGE(L3,M3,N3),Table117821341[[#This Row],[Pos.]]="TE2",AVERAGE(L3,M3,N3),Table117821341[[#This Row],[Pos.]]="D/ST",AVERAGE(Table117821341[[#This Row],[*TD*]]))} -> #N/A | X3: =AVERAGE(N3,W3) -> #N/A
B4: Q. Judklins | C4: CLE | D4: RB1 | E4: {=_xlfn.XLOOKUP(Table117821341[[#This Row],[Team]],Table4334[Team],'2425'!$C$3:$C$34)} -> n/a | F4: =_xlfn.XLOOKUP(Table117821341[[#This Row],[Team]],Table4334[Team],Table4334[OPP]) -> n/a | G4: {=IF(Table117821341[[#This Row],[Pos.]]="QB1",_xlfn.XLOOKUP(Table117821341[[#This Row],[Opp]],Table123[DEF],'2425'!$G$3:$G$34),"#N/A")} -> #N/A | H4: {=IF(Table117821341[[#This Row],[Pos.]]="QB1",_xlfn.XLOOKUP(Table117821341[[#This Row],[Opp]],Table123[DEF],'2425'!$J$3:$J$34),"#N/A")} -> #N/A | I4: {=IF(Table117821341[[#This Row],[Pos.]]="QB1",_xlfn.XLOOKUP(Table117821341[[#This Row],[Opp]],Table123[DEF],'2425'!$K$3:$K$34),"#N/A")} -> #N/A | J4: {=_xlfn.IFS(Table117821341[[#This Row],[Pos.]]="QB1",_xlfn.XLOOKUP(Table117821341[[#This Row],[Opp]],Table123[DEF],'2425'!$I$3:$I$34),Table117821341[[#This Row],[Pos.]]="RB1",_xlfn.XLOOKUP(Table117821341[[#This Row],[Opp]],Table2040[DEF],'2425'!$H$38:$H$69),Table117821341[[#This Row],[Pos.]]="RB2",_xlfn.XLOOKUP(Table117821341[[#This Row],[Opp]],Table2040[DEF],'2425'!$H$38:$H$69))} -> #N/A | K4: {=_xlfn.IFS(Table117821341[[#This Row],[Pos.]]="RB1",_xlfn.XLOOKUP(Table117821341[[#This Row],[Opp]],Table2040[DEF],'2425'!$K$38:$K$69),Table117821341[[#This Row],[Pos.]]="RB2",_xlfn.XLOOKUP(Table117821341[[#This Row],[Opp]],Table2040[DEF],'2425'!$K$38:$K$69))} -> #N/A | L4: {=_xlfn.IFS(Table117821341[[#This Row],[Pos.]]="WR1",_xlfn.XLOOKUP(Table117821341[[#This Row],[Opp]],Table731[DEF],'2425'!$U$3:$U$34),Table117821341[[#This Row],[Pos.]]="WR2",_xlfn.XLOOKUP(Table117821341[[#This Row],[Opp]],Table71236[DEF],'2425'!$AD$3:$AD$34),Table117821341[[#This Row],[Pos.]]="WR3",_xlfn.XLOOKUP(Table117821341[[#This Row],[Opp]],Table7121437[DEF],'2425'!$U$38:$U$69),Table117821341[[#This Row],[Pos.]]="WR4",_xlfn.XLOOKUP(Table117821341[[#This Row],[Opp]],Table712141538[DEF],'2425'!$AD$38:$AD$69),Table117821341[[#This Row],[Pos.]]="TE1",_xlfn.XLOOKUP(Table117821341[[#This Row],[Opp]],Table832[DEF],'2425'!$AM$3:$AM$34),Table117821341[[#This Row],[Pos.]]="TE2",_xlfn.XLOOKUP(Table117821341[[#This Row],[Opp]],Table832[DEF],'2425'!$AM$3:$AM$34),Table117821341[[#This Row],[Pos.]]="RB1",_xlfn.XLOOKUP(Table117821341[[#This Row],[Opp]],Table2040[DEF],'2425'!$I$38:$I$69),Table117821341[[#This Row],[Pos.]]="RB2",_xlfn.XLOOKUP(Table117821341[[#This Row],[Opp]],Table2040[DEF],'2425'!$I$38:$I$69))} -> #N/A | M4: {=_xlfn.IFS(Table117821341[[#This Row],[Pos.]]="WR1",_xlfn.XLOOKUP(Table117821341[[#This Row],[Opp]],Table731[DEF],'2425'!$V$3:$V$34),Table117821341[[#This Row],[Pos.]]="WR2",_xlfn.XLOOKUP(Table117821341[[#This Row],[Opp]],Table71236[DEF],'2425'!$AE$3:$AE$34),Table117821341[[#This Row],[Pos.]]="WR3",_xlfn.XLOOKUP(Table117821341[[#This Row],[Opp]],Table7121437[DEF],'2425'!$V$38:$V$69),Table117821341[[#This Row],[Pos.]]="WR4",_xlfn.XLOOKUP(Table117821341[[#This Row],[Opp]],Table712141538[DEF],'2425'!$AE$38:$AE$69),Table117821341[[#This Row],[Pos.]]="TE1",_xlfn.XLOOKUP(Table117821341[[#This Row],[Opp]],Table832[DEF],'2425'!$AN$3:$AN$34),Table117821341[[#This Row],[Pos.]]="TE2",_xlfn.XLOOKUP(Table117821341[[#This Row],[Opp]],Table832[DEF],'2425'!$AN$3:$AN$34),Table117821341[[#This Row],[Pos.]]="RB1",_xlfn.XLOOKUP(Table117821341[[#This Row],[Opp]],Table2040[DEF],'2425'!$J$38:$J$69),Table117821341[[#This Row],[Pos.]]="RB2",_xlfn.XLOOKUP(Table117821341[[#This Row],[Opp]],Table2040[DEF],'2425'!$J$38:$J$69))} -> #N/A | N4: {=_xlfn.IFS(Table117821341[[#This Row],[Pos.]]="WR1",_xlfn.XLOOKUP(Table117821341[[#This Row],[Opp]],Table731[DEF],'2425'!$W$3:$W$34),Table117821341[[#This Row],[Pos.]]="WR2",_xlfn.XLOOKUP(Table117821341[[#This Row],[Opp]],Table71236[DEF],'2425'!$AF$3:$AF$34),Table117821341[[#This Row],[Pos.]]="WR3",_xlfn.XLOOKUP(Table117821341[[#This Row],[Opp]],Table7121437[DEF],'2425'!$W$38:$W$69),Table117821341[[#This Row],[Pos.]]="WR4",_xlfn.XLOOKUP(Table117821341[[#This Row],[Opp]],Table712141538[DEF],'2425'!$AF$38:$AF$69),Table117821341[[#This Row],[Pos.]]="QB1",_xlfn.XLOOKUP(Table117821341[[#This Row],[Opp]],Table123[DEF],'2425'!$L$3:$L$34),Table117821341[[#This Row],[Pos.]]="RB1",_xlfn.XLOOKUP(Table117821341[[#This Row],[Opp]],Table2040[DEF],'2425'!$L$38:$L$69),Table117821341[[#This Row],[Pos.]]="RB2",_xlfn.XLOOKUP(Table117821341[[#This Row],[Opp]],Table2040[DEF],'2425'!$L$38:$L$69),Table117821341[[#This Row],[Pos.]]="TE1",_xlfn.XLOOKUP(Table117821341[[#This Row],[Opp]],Table832[DEF],'2425'!$AO$3:$AO$34),Table117821341[[#This Row],[Pos.]]="TE2",_xlfn.XLOOKUP(Table117821341[[#This Row],[Opp]],Table832[DEF],'2425'!$AO$3:$AO$34),Table117821341[[#This Row],[Pos.]]="D/ST",_xlfn.XLOOKUP(Table117821341[[#This Row],[Opp]],Table1033[DEF],'2425'!$C$38:$C$69))} -> #N/A | O4: =IF(Table117821341[[#This Row],[Pos.]]="QB1",_xlfn.XLOOKUP(Table117821341[[#This Row],[Opp]],Table123[DEF],Table123[P]),"#N/A") -> #N/A | P4: =IF(Table117821341[[#This Row],[Pos.]]="QB1",_xlfn.XLOOKUP(Table117821341[[#This Row],[Opp]],Table123[DEF],Table123[P+R]),"#N/A") -> #N/A | Q4: =IF(Table117821341[[#This Row],[Pos.]]="QB1",_xlfn.XLOOKUP(Table117821341[[#This Row],[Opp]],Table123[DEF],Table123[P TD]),"#N/A") -> #N/A | R4: {=_xlfn.IFS(Table117821341[[#This Row],[Pos.]]="QB1",_xlfn.XLOOKUP(Table117821341[[#This Row],[Opp]],Table123[DEF],Table123[R]),Table117821341[[#This Row],[Pos.]]="RB1",_xlfn.XLOOKUP(Table117821341[[#This Row],[Opp]],Table2040[DEF],Table2040[R]),Table117821341[[#This Row],[Pos.]]="RB2",_xlfn.XLOOKUP(Table117821341[[#This Row],[Opp]],Table2040[DEF],Table2040[R]))} -> #N/A | S4: {=_xlfn.IFS(Table117821341[[#This Row],[Pos.]]="RB1",_xlfn.XLOOKUP(Table117821341[[#This Row],[Opp]],Table2040[DEF],Table2040[R+R]),Table117821341[[#This Row],[Pos.]]="RB2",_xlfn.XLOOKUP(Table117821341[[#This Row],[Opp]],Table2040[DEF],Table2040[R+R]))} -> #N/A | T4: {=_xlfn.IFS(Table117821341[[#This Row],[Pos.]]="RB1",_xlfn.XLOOKUP(Table117821341[[#This Row],[Opp]],Table2040[DEF],Table2040[REC]),Table117821341[[#This Row],[Pos.]]="RB2",_xlfn.XLOOKUP(Table117821341[[#This Row],[Opp]],Table2040[DEF],Table2040[REC]),Table117821341[[#This Row],[Pos.]]="WR1",_xlfn.XLOOKUP(Table117821341[[#This Row],[Opp]],Table731[DEF],Table731[REC]),Table117821341[[#This Row],[Pos.]]="WR2",_xlfn.XLOOKUP(Table117821341[[#This Row],[Opp]],Table71236[DEF],Table71236[REC]),Table117821341[[#This Row],[Pos.]]="WR3",_xlfn.XLOOKUP(Table117821341[[#This Row],[Opp]],Table7121437[DEF],Table7121437[REC]),Table117821341[[#This Row],[Pos.]]="WR4",_xlfn.XLOOKUP(Table117821341[[#This Row],[Opp]],Table712141538[DEF],Table712141538[REC]),Table117821341[[#This Row],[Pos.]]="TE1",_xlfn.XLOOKUP(Table117821341[[#This Row],[Opp]],Table832[DEF],Table832[REC]),Table117821341[[#This Row],[Pos.]]="TE2",_xlfn.XLOOKUP(Table117821341[[#This Row],[Opp]],Table832[DEF],Table832[REC]))} -> #N/A | U4: {=_xlfn.IFS(Table117821341[[#This Row],[Pos.]]="RB1",_xlfn.XLOOKUP(Table117821341[[#This Row],[Opp]],Table2040[DEF],Table2040[Y]),Table117821341[[#This Row],[Pos.]]="RB2",_xlfn.XLOOKUP(Table117821341[[#This Row],[Opp]],Table2040[DEF],Table2040[Y]),Table117821341[[#This Row],[Pos.]]="WR1",_xlfn.XLOOKUP(Table117821341[[#This Row],[Opp]],Table731[DEF],Table731[Y]),Table117821341[[#This Row],[Pos.]]="WR2",_xlfn.XLOOKUP(Table117821341[[#This Row],[Opp]],Table71236[DEF],Table71236[Y]),Table117821341[[#This Row],[Pos.]]="WR3",_xlfn.XLOOKUP(Table117821341[[#This Row],[Opp]],Table7121437[DEF],Table7121437[Y]),Table117821341[[#This Row],[Pos.]]="WR4",_xlfn.XLOOKUP(Table117821341[[#This Row],[Opp]],Table712141538[DEF],Table712141538[Y]),Table117821341[[#This Row],[Pos.]]="TE1",_xlfn.XLOOKUP(Table117821341[[#This Row],[Opp]],Table832[DEF],Table832[Y]),Table117821341[[#This Row],[Pos.]]="TE2",_xlfn.XLOOKUP(Table117821341[[#This Row],[Opp]],Table832[DEF],Table832[Y]))} -> #N/A | V4: {=_xlfn.IFS(Table117821341[[#This Row],[Pos.]]="QB1",_xlfn.XLOOKUP(Table117821341[[#This Row],[Opp]],Table123[DEF],Table123[TD]),Table117821341[[#This Row],[Pos.]]="RB1",_xlfn.XLOOKUP(Table117821341[[#This Row],[Opp]],Table2040[DEF],Table2040[TD]),Table117821341[[#This Row],[Pos.]]="RB2",_xlfn.XLOOKUP(Table117821341[[#This Row],[Opp]],Table2040[DEF],Table2040[TD]),Table117821341[[#This Row],[Pos.]]="WR1",_xlfn.XLOOKUP(Table117821341[[#This Row],[Opp]],Table731[DEF],Table731[TD]),Table117821341[[#This Row],[Pos.]]="WR2",_xlfn.XLOOKUP(Table117821341[[#This Row],[Opp]],Table71236[DEF],Table71236[TD]),Table117821341[[#This Row],[Pos.]]="WR3",_xlfn.XLOOKUP(Table117821341[[#This Row],[Opp]],Table7121437[DEF],Table7121437[TD]),Table117821341[[#This Row],[Pos.]]="WR4",_xlfn.XLOOKUP(Table117821341[[#This Row],[Opp]],Table712141538[DEF],Table712141538[TD]),Table117821341[[#This Row],[Pos.]]="TE1",_xlfn.XLOOKUP(Table117821341[[#This Row],[Opp]],Table832[DEF],Table832[TD]),Table117821341[[#This Row],[Pos.]]="TE2",_xlfn.XLOOKUP(Table117821341[[#This Row],[Opp]],Table832[DEF],Table832[TD]),Table117821341[[#This Row],[Pos.]]="D/ST",_xlfn.XLOOKUP(Table117821341[[#This Row],[Opp]],Table1033[DEF],Table1033[TD]))} -> #N/A | W4: {=_xlfn.IFS(Table117821341[[#This Row],[Pos.]]="QB1",AVERAGE(G4,H4,I4,J4,N4),Table117821341[[#This Row],[Pos.]]="RB1",AVERAGE(J4,K4,N4),Table117821341[[#This Row],[Pos.]]="RB2",AVERAGE(J4,K4,N4),Table117821341[[#This Row],[Pos.]]="WR1",AVERAGE(L4,M4,N4),Table117821341[[#This Row],[Pos.]]="WR2",AVERAGE(L4,M4,N4),Table117821341[[#This Row],[Pos.]]="WR3",AVERAGE(L4,M4,N4),Table117821341[[#This Row],[Pos.]]="WR4",AVERAGE(L4,M4,N4),Table117821341[[#This Row],[Pos.]]="TE1",AVERAGE(L4,M4,N4),Table117821341[[#This Row],[Pos.]]="TE2",AVERAGE(L4,M4,N4),Table117821341[[#This Row],[Pos.]]="D/ST",AVERAGE(Table117821341[[#This Row],[*TD*]]))} -> #N/A | X4: =AVERAGE(N4,W4) -> #N/A
B5: J. Brissett | C5: ARI | D5: QB2 | E5: {=_xlfn.XLOOKUP(Table117821341[[#This Row],[Team]],Table4334[Team],'2425'!$C$3:$C$34)} -> n/a | F5: =_xlfn.XLOOKUP(Table117821341[[#This Row],[Team]],Table4334[Team],Table4334[OPP]) -> n/a | G5: {=IF(Table117821341[[#This Row],[Pos.]]="QB1",_xlfn.XLOOKUP(Table117821341[[#This Row],[Opp]],Table123[DEF],'2425'!$G$3:$G$34),"#N/A")} -> #N/A | H5: {=IF(Table117821341[[#This Row],[Pos.]]="QB1",_xlfn.XLOOKUP(Table117821341[[#This Row],[Opp]],Table123[DEF],'2425'!$J$3:$J$34),"#N/A")} -> #N/A | I5: {=IF(Table117821341[[#This Row],[Pos.]]="QB1",_xlfn.XLOOKUP(Table117821341[[#This Row],[Opp]],Table123[DEF],'2425'!$K$3:$K$34),"#N/A")} -> #N/A | J5: {=_xlfn.IFS(Table117821341[[#This Row],[Pos.]]="QB1",_xlfn.XLOOKUP(Table117821341[[#This Row],[Opp]],Table123[DEF],'2425'!$I$3:$I$34),Table117821341[[#This Row],[Pos.]]="RB1",_xlfn.XLOOKUP(Table117821341[[#This Row],[Opp]],Table2040[DEF],'2425'!$H$38:$H$69),Table117821341[[#This Row],[Pos.]]="RB2",_xlfn.XLOOKUP(Table117821341[[#This Row],[Opp]],Table2040[DEF],'2425'!$H$38:$H$69))} -> #N/A | K5: {=_xlfn.IFS(Table117821341[[#This Row],[Pos.]]="RB1",_xlfn.XLOOKUP(Table117821341[[#This Row],[Opp]],Table2040[DEF],'2425'!$K$38:$K$69),Table117821341[[#This Row],[Pos.]]="RB2",_xlfn.XLOOKUP(Table117821341[[#This Row],[Opp]],Table2040[DEF],'2425'!$K$38:$K$69))} -> #N/A | L5: {=_xlfn.IFS(Table117821341[[#This Row],[Pos.]]="WR1",_xlfn.XLOOKUP(Table117821341[[#This Row],[Opp]],Table731[DEF],'2425'!$U$3:$U$34),Table117821341[[#This Row],[Pos.]]="WR2",_xlfn.XLOOKUP(Table117821341[[#This Row],[Opp]],Table71236[DEF],'2425'!$AD$3:$AD$34),Table117821341[[#This Row],[Pos.]]="WR3",_xlfn.XLOOKUP(Table117821341[[#This Row],[Opp]],Table7121437[DEF],'2425'!$U$38:$U$69),Table117821341[[#This Row],[Pos.]]="WR4",_xlfn.XLOOKUP(Table117821341[[#This Row],[Opp]],Table712141538[DEF],'2425'!$AD$38:$AD$69),Table117821341[[#This Row],[Pos.]]="TE1",_xlfn.XLOOKUP(Table117821341[[#This Row],[Opp]],Table832[DEF],'2425'!$AM$3:$AM$34),Table117821341[[#This Row],[Pos.]]="TE2",_xlfn.XLOOKUP(Table117821341[[#This Row],[Opp]],Table832[DEF],'2425'!$AM$3:$AM$34),Table117821341[[#This Row],[Pos.]]="RB1",_xlfn.XLOOKUP(Table117821341[[#This Row],[Opp]],Table2040[DEF],'2425'!$I$38:$I$69),Table117821341[[#This Row],[Pos.]]="RB2",_xlfn.XLOOKUP(Table117821341[[#This Row],[Opp]],Table2040[DEF],'2425'!$I$38:$I$69))} -> #N/A | M5: {=_xlfn.IFS(Table117821341[[#This Row],[Pos.]]="WR1",_xlfn.XLOOKUP(Table117821341[[#This Row],[Opp]],Table731[DEF],'2425'!$V$3:$V$34),Table117821341[[#This Row],[Pos.]]="WR2",_xlfn.XLOOKUP(Table117821341[[#This Row],[Opp]],Table71236[DEF],'2425'!$AE$3:$AE$34),Table117821341[[#This Row],[Pos.]]="WR3",_xlfn.XLOOKUP(Table117821341[[#This Row],[Opp]],Table7121437[DEF],'2425'!$V$38:$V$69),Table117821341[[#This Row],[Pos.]]="WR4",_xlfn.XLOOKUP(Table117821341[[#This Row],[Opp]],Table712141538[DEF],'2425'!$AE$38:$AE$69),Table117821341[[#This Row],[Pos.]]="TE1",_xlfn.XLOOKUP(Table117821341[[#This Row],[Opp]],Table832[DEF],'2425'!$AN$3:$AN$34),Table117821341[[#This Row],[Pos.]]="TE2",_xlfn.XLOOKUP(Table117821341[[#This Row],[Opp]],Table832[DEF],'2425'!$AN$3:$AN$34),Table117821341[[#This Row],[Pos.]]="RB1",_xlfn.XLOOKUP(Table117821341[[#This Row],[Opp]],Table2040[DEF],'2425'!$J$38:$J$69),Table117821341[[#This Row],[Pos.]]="RB2",_xlfn.XLOOKUP(Table117821341[[#This Row],[Opp]],Table2040[DEF],'2425'!$J$38:$J$69))} -> #N/A | N5: {=_xlfn.IFS(Table117821341[[#This Row],[Pos.]]="WR1",_xlfn.XLOOKUP(Table117821341[[#This Row],[Opp]],Table731[DEF],'2425'!$W$3:$W$34),Table117821341[[#This Row],[Pos.]]="WR2",_xlfn.XLOOKUP(Table117821341[[#This Row],[Opp]],Table71236[DEF],'2425'!$AF$3:$AF$34),Table117821341[[#This Row],[Pos.]]="WR3",_xlfn.XLOOKUP(Table117821341[[#This Row],[Opp]],Table7121437[DEF],'2425'!$W$38:$W$69),Table117821341[[#This Row],[Pos.]]="WR4",_xlfn.XLOOKUP(Table117821341[[#This Row],[Opp]],Table712141538[DEF],'2425'!$AF$38:$AF$69),Table117821341[[#This Row],[Pos.]]="QB1",_xlfn.XLOOKUP(Table117821341[[#This Row],[Opp]],Table123[DEF],'2425'!$L$3:$L$34),Table117821341[[#This Row],[Pos.]]="RB1",_xlfn.XLOOKUP(Table117821341[[#This Row],[Opp]],Table2040[DEF],'2425'!$L$38:$L$69),Table117821341[[#This Row],[Pos.]]="RB2",_xlfn.XLOOKUP(Table117821341[[#This Row],[Opp]],Table2040[DEF],'2425'!$L$38:$L$69),Table117821341[[#This Row],[Pos.]]="TE1",_xlfn.XLOOKUP(Table117821341[[#This Row],[Opp]],Table832[DEF],'2425'!$AO$3:$AO$34),Table117821341[[#This Row],[Pos.]]="TE2",_xlfn.XLOOKUP(Table117821341[[#This Row],[Opp]],Table832[DEF],'2425'!$AO$3:$AO$34),Table117821341[[#This Row],[Pos.]]="D/ST",_xlfn.XLOOKUP(Table117821341[[#This Row],[Opp]],Table1033[DEF],'2425'!$C$38:$C$69))} -> #N/A | O5: =IF(Table117821341[[#This Row],[Pos.]]="QB1",_xlfn.XLOOKUP(Table117821341[[#This Row],[Opp]],Table123[DEF],Table123[P]),"#N/A") -> #N/A | P5: =IF(Table117821341[[#This Row],[Pos.]]="QB1",_xlfn.XLOOKUP(Table117821341[[#This Row],[Opp]],Table123[DEF],Table123[P+R]),"#N/A") -> #N/A | Q5: =IF(Table117821341[[#This Row],[Pos.]]="QB1",_xlfn.XLOOKUP(Table117821341[[#This Row],[Opp]],Table123[DEF],Table123[P TD]),"#N/A") -> #N/A | R5: {=_xlfn.IFS(Table117821341[[#This Row],[Pos.]]="QB1",_xlfn.XLOOKUP(Table117821341[[#This Row],[Opp]],Table123[DEF],Table123[R]),Table117821341[[#This Row],[Pos.]]="RB1",_xlfn.XLOOKUP(Table117821341[[#This Row],[Opp]],Table2040[DEF],Table2040[R]),Table117821341[[#This Row],[Pos.]]="RB2",_xlfn.XLOOKUP(Table117821341[[#This Row],[Opp]],Table2040[DEF],Table2040[R]))} -> #N/A | S5: {=_xlfn.IFS(Table117821341[[#This Row],[Pos.]]="RB1",_xlfn.XLOOKUP(Table117821341[[#This Row],[Opp]],Table2040[DEF],Table2040[R+R]),Table117821341[[#This Row],[Pos.]]="RB2",_xlfn.XLOOKUP(Table117821341[[#This Row],[Opp]],Table2040[DEF],Table2040[R+R]))} -> #N/A | T5: {=_xlfn.IFS(Table117821341[[#This Row],[Pos.]]="RB1",_xlfn.XLOOKUP(Table117821341[[#This Row],[Opp]],Table2040[DEF],Table2040[REC]),Table117821341[[#This Row],[Pos.]]="RB2",_xlfn.XLOOKUP(Table117821341[[#This Row],[Opp]],Table2040[DEF],Table2040[REC]),Table117821341[[#This Row],[Pos.]]="WR1",_xlfn.XLOOKUP(Table117821341[[#This Row],[Opp]],Table731[DEF],Table731[REC]),Table117821341[[#This Row],[Pos.]]="WR2",_xlfn.XLOOKUP(Table117821341[[#This Row],[Opp]],Table71236[DEF],Table71236[REC]),Table117821341[[#This Row],[Pos.]]="WR3",_xlfn.XLOOKUP(Table117821341[[#This Row],[Opp]],Table7121437[DEF],Table7121437[REC]),Table117821341[[#This Row],[Pos.]]="WR4",_xlfn.XLOOKUP(Table117821341[[#This Row],[Opp]],Table712141538[DEF],Table712141538[REC]),Table117821341[[#This Row],[Pos.]]="TE1",_xlfn.XLOOKUP(Table117821341[[#This Row],[Opp]],Table832[DEF],Table832[REC]),Table117821341[[#This Row],[Pos.]]="TE2",_xlfn.XLOOKUP(Table117821341[[#This Row],[Opp]],Table832[DEF],Table832[REC]))} -> #N/A | U5: {=_xlfn.IFS(Table117821341[[#This Row],[Pos.]]="RB1",_xlfn.XLOOKUP(Table117821341[[#This Row],[Opp]],Table2040[DEF],Table2040[Y]),Table117821341[[#This Row],[Pos.]]="RB2",_xlfn.XLOOKUP(Table117821341[[#This Row],[Opp]],Table2040[DEF],Table2040[Y]),Table117821341[[#This Row],[Pos.]]="WR1",_xlfn.XLOOKUP(Table117821341[[#This Row],[Opp]],Table731[DEF],Table731[Y]),Table117821341[[#This Row],[Pos.]]="WR2",_xlfn.XLOOKUP(Table117821341[[#This Row],[Opp]],Table71236[DEF],Table71236[Y]),Table117821341[[#This Row],[Pos.]]="WR3",_xlfn.XLOOKUP(Table117821341[[#This Row],[Opp]],Table7121437[DEF],Table7121437[Y]),Table117821341[[#This Row],[Pos.]]="WR4",_xlfn.XLOOKUP(Table117821341[[#This Row],[Opp]],Table712141538[DEF],Table712141538[Y]),Table117821341[[#This Row],[Pos.]]="TE1",_xlfn.XLOOKUP(Table117821341[[#This Row],[Opp]],Table832[DEF],Table832[Y]),Table117821341[[#This Row],[Pos.]]="TE2",_xlfn.XLOOKUP(Table117821341[[#This Row],[Opp]],Table832[DEF],Table832[Y]))} -> #N/A | V5: {=_xlfn.IFS(Table117821341[[#This Row],[Pos.]]="QB1",_xlfn.XLOOKUP(Table117821341[[#This Row],[Opp]],Table123[DEF],Table123[TD]),Table117821341[[#This Row],[Pos.]]="RB1",_xlfn.XLOOKUP(Table117821341[[#This Row],[Opp]],Table2040[DEF],Table2040[TD]),Table117821341[[#This Row],[Pos.]]="RB2",_xlfn.XLOOKUP(Table117821341[[#This Row],[Opp]],Table2040[DEF],Table2040[TD]),Table117821341[[#This Row],[Pos.]]="WR1",_xlfn.XLOOKUP(Table117821341[[#This Row],[Opp]],Table731[DEF],Table731[TD]),Table117821341[[#This Row],[Pos.]]="WR2",_xlfn.XLOOKUP(Table117821341[[#This Row],[Opp]],Table71236[DEF],Table71236[TD]),Table117821341[[#This Row],[Pos.]]="WR3",_xlfn.XLOOKUP(Table117821341[[#This Row],[Opp]],Table7121437[DEF],Table7121437[TD]),Table117821341[[#This Row],[Pos.]]="WR4",_xlfn.XLOOKUP(Table117821341[[#This Row],[Opp]],Table712141538[DEF],Table712141538[TD]),Table117821341[[#This Row],[Pos.]]="TE1",_xlfn.XLOOKUP(Table117821341[[#This Row],[Opp]],Table832[DEF],Table832[TD]),Table117821341[[#This Row],[Pos.]]="TE2",_xlfn.XLOOKUP(Table117821341[[#This Row],[Opp]],Table832[DEF],Table832[TD]),Table117821341[[#This Row],[Pos.]]="D/ST",_xlfn.XLOOKUP(Table117821341[[#This Row],[Opp]],Table1033[DEF],Table1033[TD]))} -> #N/A | W5: {=_xlfn.IFS(Table117821341[[#This Row],[Pos.]]="QB1",AVERAGE(G5,H5,I5,J5,N5),Table117821341[[#This Row],[Pos.]]="RB1",AVERAGE(J5,K5,N5),Table117821341[[#This Row],[Pos.]]="RB2",AVERAGE(J5,K5,N5),Table117821341[[#This Row],[Pos.]]="WR1",AVERAGE(L5,M5,N5),Table117821341[[#This Row],[Pos.]]="WR2",AVERAGE(L5,M5,N5),Table117821341[[#This Row],[Pos.]]="WR3",AVERAGE(L5,M5,N5),Table117821341[[#This Row],[Pos.]]="WR4",AVERAGE(L5,M5,N5),Table117821341[[#This Row],[Pos.]]="TE1",AVERAGE(L5,M5,N5),Table117821341[[#This Row],[Pos.]]="TE2",AVERAGE(L5,M5,N5),Table117821341[[#This Row],[Pos.]]="D/ST",AVERAGE(Table117821341[[#This Row],[*TD*]]))} -> #N/A | X5: =AVERAGE(N5,W5) -> #N/A
B6: B. Hall | C6: NYJ | D6: RB1 | E6: {=_xlfn.XLOOKUP(Table117821341[[#This Row],[Team]],Table4334[Team],'2425'!$C$3:$C$34)} -> n/a | F6: =_xlfn.XLOOKUP(Table117821341[[#This Row],[Team]],Table4334[Team],Table4334[OPP]) -> n/a | G6: {=IF(Table117821341[[#This Row],[Pos.]]="QB1",_xlfn.XLOOKUP(Table117821341[[#This Row],[Opp]],Table123[DEF],'2425'!$G$3:$G$34),"#N/A")} -> #N/A | H6: {=IF(Table117821341[[#This Row],[Pos.]]="QB1",_xlfn.XLOOKUP(Table117821341[[#This Row],[Opp]],Table123[DEF],'2425'!$J$3:$J$34),"#N/A")} -> #N/A | I6: {=IF(Table117821341[[#This Row],[Pos.]]="QB1",_xlfn.XLOOKUP(Table117821341[[#This Row],[Opp]],Table123[DEF],'2425'!$K$3:$K$34),"#N/A")} -> #N/A | J6: {=_xlfn.IFS(Table117821341[[#This Row],[Pos.]]="QB1",_xlfn.XLOOKUP(Table117821341[[#This Row],[Opp]],Table123[DEF],'2425'!$I$3:$I$34),Table117821341[[#This Row],[Pos.]]="RB1",_xlfn.XLOOKUP(Table117821341[[#This Row],[Opp]],Table2040[DEF],'2425'!$H$38:$H$69),Table117821341[[#This Row],[Pos.]]="RB2",_xlfn.XLOOKUP(Table117821341[[#This Row],[Opp]],Table2040[DEF],'2425'!$H$38:$H$69))} -> #N/A | K6: {=_xlfn.IFS(Table117821341[[#This Row],[Pos.]]="RB1",_xlfn.XLOOKUP(Table117821341[[#This Row],[Opp]],Table2040[DEF],'2425'!$K$38:$K$69),Table117821341[[#This Row],[Pos.]]="RB2",_xlfn.XLOOKUP(Table117821341[[#This Row],[Opp]],Table2040[DEF],'2425'!$K$38:$K$69))} -> #N/A | L6: {=_xlfn.IFS(Table117821341[[#This Row],[Pos.]]="WR1",_xlfn.XLOOKUP(Table117821341[[#This Row],[Opp]],Table731[DEF],'2425'!$U$3:$U$34),Table117821341[[#This Row],[Pos.]]="WR2",_xlfn.XLOOKUP(Table117821341[[#This Row],[Opp]],Table71236[DEF],'2425'!$AD$3:$AD$34),Table117821341[[#This Row],[Pos.]]="WR3",_xlfn.XLOOKUP(Table117821341[[#This Row],[Opp]],Table7121437[DEF],'2425'!$U$38:$U$69),Table117821341[[#This Row],[Pos.]]="WR4",_xlfn.XLOOKUP(Table117821341[[#This Row],[Opp]],Table712141538[DEF],'2425'!$AD$38:$AD$69),Table117821341[[#This Row],[Pos.]]="TE1",_xlfn.XLOOKUP(Table117821341[[#This Row],[Opp]],Table832[DEF],'2425'!$AM$3:$AM$34),Table117821341[[#This Row],[Pos.]]="TE2",_xlfn.XLOOKUP(Table117821341[[#This Row],[Opp]],Table832[DEF],'2425'!$AM$3:$AM$34),Table117821341[[#This Row],[Pos.]]="RB1",_xlfn.XLOOKUP(Table117821341[[#This Row],[Opp]],Table2040[DEF],'2425'!$I$38:$I$69),Table117821341[[#This Row],[Pos.]]="RB2",_xlfn.XLOOKUP(Table117821341[[#This Row],[Opp]],Table2040[DEF],'2425'!$I$38:$I$69))} -> #N/A | M6: {=_xlfn.IFS(Table117821341[[#This Row],[Pos.]]="WR1",_xlfn.XLOOKUP(Table117821341[[#This Row],[Opp]],Table731[DEF],'2425'!$V$3:$V$34),Table117821341[[#This Row],[Pos.]]="WR2",_xlfn.XLOOKUP(Table117821341[[#This Row],[Opp]],Table71236[DEF],'2425'!$AE$3:$AE$34),Table117821341[[#This Row],[Pos.]]="WR3",_xlfn.XLOOKUP(Table117821341[[#This Row],[Opp]],Table7121437[DEF],'2425'!$V$38:$V$69),Table117821341[[#This Row],[Pos.]]="WR4",_xlfn.XLOOKUP(Table117821341[[#This Row],[Opp]],Table712141538[DEF],'2425'!$AE$38:$AE$69),Table117821341[[#This Row],[Pos.]]="TE1",_xlfn.XLOOKUP(Table117821341[[#This Row],[Opp]],Table832[DEF],'2425'!$AN$3:$AN$34),Table117821341[[#This Row],[Pos.]]="TE2",_xlfn.XLOOKUP(Table117821341[[#This Row],[Opp]],Table832[DEF],'2425'!$AN$3:$AN$34),Table117821341[[#This Row],[Pos.]]="RB1",_xlfn.XLOOKUP(Table117821341[[#This Row],[Opp]],Table2040[DEF],'2425'!$J$38:$J$69),Table117821341[[#This Row],[Pos.]]="RB2",_xlfn.XLOOKUP(Table117821341[[#This Row],[Opp]],Table2040[DEF],'2425'!$J$38:$J$69))} -> #N/A | N6: {=_xlfn.IFS(Table117821341[[#This Row],[Pos.]]="WR1",_xlfn.XLOOKUP(Table117821341[[#This Row],[Opp]],Table731[DEF],'2425'!$W$3:$W$34),Table117821341[[#This Row],[Pos.]]="WR2",_xlfn.XLOOKUP(Table117821341[[#This Row],[Opp]],Table71236[DEF],'2425'!$AF$3:$AF$34),Table117821341[[#This Row],[Pos.]]="WR3",_xlfn.XLOOKUP(Table117821341[[#This Row],[Opp]],Table7121437[DEF],'2425'!$W$38:$W$69),Table117821341[[#This Row],[Pos.]]="WR4",_xlfn.XLOOKUP(Table117821341[[#This Row],[Opp]],Table712141538[DEF],'2425'!$AF$38:$AF$69),Table117821341[[#This Row],[Pos.]]="QB1",_xlfn.XLOOKUP(Table117821341[[#This Row],[Opp]],Table123[DEF],'2425'!$L$3:$L$34),Table117821341[[#This Row],[Pos.]]="RB1",_xlfn.XLOOKUP(Table117821341[[#This Row],[Opp]],Table2040[DEF],'2425'!$L$38:$L$69),Table117821341[[#This Row],[Pos.]]="RB2",_xlfn.XLOOKUP(Table117821341[[#This Row],[Opp]],Table2040[DEF],'2425'!$L$38:$L$69),Table117821341[[#This Row],[Pos.]]="TE1",_xlfn.XLOOKUP(Table117821341[[#This Row],[Opp]],Table832[DEF],'2425'!$AO$3:$AO$34),Table117821341[[#This Row],[Pos.]]="TE2",_xlfn.XLOOKUP(Table117821341[[#This Row],[Opp]],Table832[DEF],'2425'!$AO$3:$AO$34),Table117821341[[#This Row],[Pos.]]="D/ST",_xlfn.XLOOKUP(Table117821341[[#This Row],[Opp]],Table1033[DEF],'2425'!$C$38:$C$69))} -> #N/A | O6: =IF(Table117821341[[#This Row],[Pos.]]="QB1",_xlfn.XLOOKUP(Table117821341[[#This Row],[Opp]],Table123[DEF],Table123[P]),"#N/A") -> #N/A | P6: =IF(Table117821341[[#This Row],[Pos.]]="QB1",_xlfn.XLOOKUP(Table117821341[[#This Row],[Opp]],Table123[DEF],Table123[P+R]),"#N/A") -> #N/A | Q6: =IF(Table117821341[[#This Row],[Pos.]]="QB1",_xlfn.XLOOKUP(Table117821341[[#This Row],[Opp]],Table123[DEF],Table123[P TD]),"#N/A") -> #N/A | R6: {=_xlfn.IFS(Table117821341[[#This Row],[Pos.]]="QB1",_xlfn.XLOOKUP(Table117821341[[#This Row],[Opp]],Table123[DEF],Table123[R]),Table117821341[[#This Row],[Pos.]]="RB1",_xlfn.XLOOKUP(Table117821341[[#This Row],[Opp]],Table2040[DEF],Table2040[R]),Table117821341[[#This Row],[Pos.]]="RB2",_xlfn.XLOOKUP(Table117821341[[#This Row],[Opp]],Table2040[DEF],Table2040[R]))} -> #N/A | S6: {=_xlfn.IFS(Table117821341[[#This Row],[Pos.]]="RB1",_xlfn.XLOOKUP(Table117821341[[#This Row],[Opp]],Table2040[DEF],Table2040[R+R]),Table117821341[[#This Row],[Pos.]]="RB2",_xlfn.XLOOKUP(Table117821341[[#This Row],[Opp]],Table2040[DEF],Table2040[R+R]))} -> #N/A | T6: {=_xlfn.IFS(Table117821341[[#This Row],[Pos.]]="RB1",_xlfn.XLOOKUP(Table117821341[[#This Row],[Opp]],Table2040[DEF],Table2040[REC]),Table117821341[[#This Row],[Pos.]]="RB2",_xlfn.XLOOKUP(Table117821341[[#This Row],[Opp]],Table2040[DEF],Table2040[REC]),Table117821341[[#This Row],[Pos.]]="WR1",_xlfn.XLOOKUP(Table117821341[[#This Row],[Opp]],Table731[DEF],Table731[REC]),Table117821341[[#This Row],[Pos.]]="WR2",_xlfn.XLOOKUP(Table117821341[[#This Row],[Opp]],Table71236[DEF],Table71236[REC]),Table117821341[[#This Row],[Pos.]]="WR3",_xlfn.XLOOKUP(Table117821341[[#This Row],[Opp]],Table7121437[DEF],Table7121437[REC]),Table117821341[[#This Row],[Pos.]]="WR4",_xlfn.XLOOKUP(Table117821341[[#This Row],[Opp]],Table712141538[DEF],Table712141538[REC]),Table117821341[[#This Row],[Pos.]]="TE1",_xlfn.XLOOKUP(Table117821341[[#This Row],[Opp]],Table832[DEF],Table832[REC]),Table117821341[[#This Row],[Pos.]]="TE2",_xlfn.XLOOKUP(Table117821341[[#This Row],[Opp]],Table832[DEF],Table832[REC]))} -> #N/A | U6: {=_xlfn.IFS(Table117821341[[#This Row],[Pos.]]="RB1",_xlfn.XLOOKUP(Table117821341[[#This Row],[Opp]],Table2040[DEF],Table2040[Y]),Table117821341[[#This Row],[Pos.]]="RB2",_xlfn.XLOOKUP(Table117821341[[#This Row],[Opp]],Table2040[DEF],Table2040[Y]),Table117821341[[#This Row],[Pos.]]="WR1",_xlfn.XLOOKUP(Table117821341[[#This Row],[Opp]],Table731[DEF],Table731[Y]),Table117821341[[#This Row],[Pos.]]="WR2",_xlfn.XLOOKUP(Table117821341[[#This Row],[Opp]],Table71236[DEF],Table71236[Y]),Table117821341[[#This Row],[Pos.]]="WR3",_xlfn.XLOOKUP(Table117821341[[#This Row],[Opp]],Table7121437[DEF],Table7121437[Y]),Table117821341[[#This Row],[Pos.]]="WR4",_xlfn.XLOOKUP(Table117821341[[#This Row],[Opp]],Table712141538[DEF],Table712141538[Y]),Table117821341[[#This Row],[Pos.]]="TE1",_xlfn.XLOOKUP(Table117821341[[#This Row],[Opp]],Table832[DEF],Table832[Y]),Table117821341[[#This Row],[Pos.]]="TE2",_xlfn.XLOOKUP(Table117821341[[#This Row],[Opp]],Table832[DEF],Table832[Y]))} -> #N/A | V6: {=_xlfn.IFS(Table117821341[[#This Row],[Pos.]]="QB1",_xlfn.XLOOKUP(Table117821341[[#This Row],[Opp]],Table123[DEF],Table123[TD]),Table117821341[[#This Row],[Pos.]]="RB1",_xlfn.XLOOKUP(Table117821341[[#This Row],[Opp]],Table2040[DEF],Table2040[TD]),Table117821341[[#This Row],[Pos.]]="RB2",_xlfn.XLOOKUP(Table117821341[[#This Row],[Opp]],Table2040[DEF],Table2040[TD]),Table117821341[[#This Row],[Pos.]]="WR1",_xlfn.XLOOKUP(Table117821341[[#This Row],[Opp]],Table731[DEF],Table731[TD]),Table117821341[[#This Row],[Pos.]]="WR2",_xlfn.XLOOKUP(Table117821341[[#This Row],[Opp]],Table71236[DEF],Table71236[TD]),Table117821341[[#This Row],[Pos.]]="WR3",_xlfn.XLOOKUP(Table117821341[[#This Row],[Opp]],Table7121437[DEF],Table7121437[TD]),Table117821341[[#This Row],[Pos.]]="WR4",_xlfn.XLOOKUP(Table117821341[[#This Row],[Opp]],Table712141538[DEF],Table712141538[TD]),Table117821341[[#This Row],[Pos.]]="TE1",_xlfn.XLOOKUP(Table117821341[[#This Row],[Opp]],Table832[DEF],Table832[TD]),Table117821341[[#This Row],[Pos.]]="TE2",_xlfn.XLOOKUP(Table117821341[[#This Row],[Opp]],Table832[DEF],Table832[TD]),Table117821341[[#This Row],[Pos.]]="D/ST",_xlfn.XLOOKUP(Table117821341[[#This Row],[Opp]],Table1033[DEF],Table1033[TD]))} -> #N/A | W6: {=_xlfn.IFS(Table117821341[[#This Row],[Pos.]]="QB1",AVERAGE(G6,H6,I6,J6,N6),Table117821341[[#This Row],[Pos.]]="RB1",AVERAGE(J6,K6,N6),Table117821341[[#This Row],[Pos.]]="RB2",AVERAGE(J6,K6,N6),Table117821341[[#This Row],[Pos.]]="WR1",AVERAGE(L6,M6,N6),Table117821341[[#This Row],[Pos.]]="WR2",AVERAGE(L6,M6,N6),Table117821341[[#This Row],[Pos.]]="WR3",AVERAGE(L6,M6,N6),Table117821341[[#This Row],[Pos.]]="WR4",AVERAGE(L6,M6,N6),Table117821341[[#This Row],[Pos.]]="TE1",AVERAGE(L6,M6,N6),Table117821341[[#This Row],[Pos.]]="TE2",AVERAGE(L6,M6,N6),Table117821341[[#This Row],[Pos.]]="D/ST",AVERAGE(Table117821341[[#This Row],[*TD*]]))} -> #N/A | X6: =AVERAGE(N6,W6) -> #N/A
